Workbook

Sheet 填寫說明
B1: 武功強度設定表
B3: 這份表格做什麼 | C3: 每套武功、每個招式的「強度數字」都填在這裡。招式的文字敘述另外討論（第一部分），這裡只放數字和設定。
B4: 怎麼填 | C4: 1. 先到「武功總表」新增一列，替武功取英文代號（例如 sanmeendo）。 2. 再到「招式表」，每個招式一列，第一欄選同一個武功代號。 3. 有下拉選單的欄位直接用選的；數字欄填錯範圍會跳警告。 4. 不確定的欄位留白即可，程式會用預設值（見「欄位說明」）。
B5: 格子顏色
B6: 淡黃色 | C6: 你要填的格子
B7: 淡藍色 | C7: 範例（三門刀法），可以參考格式，也可以直接修改或刪掉
B8: 淡綠色 | C8: 自動計算，不用填
B9: 百分比怎麼填 | C9: 直接填數字：要 +15% 就填 15（不要填 0.15）。
B10: 數值參考 | C10: 「欄位說明」寫每一欄的意思和預設值；「建議範圍」列出入門／中階／高階武功的建議數字。
B11: 注意 | C11: 範例是新版三門刀法（5 招），所有數字都是建議值，尚未定案。 傷害加成、解鎖等級、消耗、冷卻、特效、出招條件都是新機制（NEW），要等引擎做好才會生效。

Sheet 武功總表
A1: 武功代號 (英文) | B1: 武功名稱 | C1: enable 在 (基本技能) | D1: 門派 | E1: 整套傷害 加成 (%) | F1: 加成方式 | G1: 招式數 (自動) | H1: 武術造詣 係數 | I1: 武學之道 起始等級 | J1: 武學之道 係數 | K1: 整套特效 | L1: 整套特效 機率 (%) | M1: 整套特效 強度 | N1: 備註
A2: sanmeendo | B2: 三門刀法 | C2: blade | D2: 虎刀門 | E2: 0 | F2: 固定 | G2: =IF(A2="","",COUNTIF(招式表!$A$2:$A$201,A2)) | H2: 10 | I2: 30 | J2: 10 | K2: 三招重演 | L2: 10 | M2: 75 | N2: 三招重演：機率 = 10% + 天生膽識÷4；需三門刀法 100、狻猊步法 60（enable）
G3: =IF(A3="","",COUNTIF(招式表!$A$2:$A$201,A3))
G4: =IF(A4="","",COUNTIF(招式表!$A$2:$A$201,A4))
G5: =IF(A5="","",COUNTIF(招式表!$A$2:$A$201,A5))
G6: =IF(A6="","",COUNTIF(招式表!$A$2:$A$201,A6))
G7: =IF(A7="","",COUNTIF(招式表!$A$2:$A$201,A7))
G8: =IF(A8="","",COUNTIF(招式表!$A$2:$A$201,A8))
G9: =IF(A9="","",COUNTIF(招式表!$A$2:$A$201,A9))
G10: =IF(A10="","",COUNTIF(招式表!$A$2:$A$201,A10))
G11: =IF(A11="","",COUNTIF(招式表!$A$2:$A$201,A11))
G12: =IF(A12="","",COUNTIF(招式表!$A$2:$A$201,A12))
G13: =IF(A13="","",COUNTIF(招式表!$A$2:$A$201,A13))
G14: =IF(A14="","",COUNTIF(招式表!$A$2:$A$201,A14))
... G201: =IF(A201="","",COUNTIF(招式表!$A$2:$A$201,A201))

Sheet 招式表
A1: 武功代號 | B1: 順序 | C1: 招式名 | D1: 解鎖 等級 | E1: 命中 加成 | F1: 防守 加成 | G1: 內力 加成 | H1: 招式傷害 加成 (%) | I1: 總傷害 加成 (%) (自動) | J1: 傷害類型 | K1: 元素 | L1: 出招 權重 | M1: 出招條件 | N1: 連招前置 (招式名) | O1: 內力 消耗 | P1: 冷卻 (回合) | Q1: 特效 | R1: 特效 機率 (%) | S1: 特效持續 (回合) | T1: 特效 強度 | U1: 備註
A2: sanmeendo | B2: 1 | C2: 開門見山 | D2: 0 | E2: 8 | F2: 3 | G2: 0 | H2: 0 | I2: =IF(A2="","",IFERROR(INDEX(武功總表!$E$2:$E$201,MATCH(A2,武功總表!$A$2:$A$201,0)),0)+N(H2)) | J2: 割傷 | K2: 無 | L2: 5 | M2: 無 | O2: 0 | P2: 0 | Q2: 無 | U2: 範例
A3: sanmeendo | B3: 2 | C3: 迴門藏鋒 | D3: 0 | E3: 6 | F3: 5 | G3: 0 | H3: 0 | I3: =IF(A3="","",IFERROR(INDEX(武功總表!$E$2:$E$201,MATCH(A3,武功總表!$A$2:$A$201,0)),0)+N(H3)) | J3: 割傷 | K3: 無 | L3: 5 | M3: 無 | O3: 0 | P3: 0 | Q3: 無 | U3: 範例
A4: sanmeendo | B4: 3 | C4: 側門截勢 | D4: 5 | E4: 7 | F4: 4 | G4: 1 | H4: 0 | I4: =IF(A4="","",IFERROR(INDEX(武功總表!$E$2:$E$201,MATCH(A4,武功總表!$A$2:$A$201,0)),0)+N(H4)) | J4: 割傷 | K4: 無 | L4: 5 | M4: 無 | O4: 0 | P4: 0 | Q4: 無 | U4: 範例
A5: sanmeendo | B5: 4 | C5: 中門直進 | D5: 10 | E5: 9 | F5: 2 | G5: 1 | H5: 5 | I5: =IF(A5="","",IFERROR(INDEX(武功總表!$E$2:$E$201,MATCH(A5,武功總表!$A$2:$A$201,0)),0)+N(H5)) | J5: 割傷 | K5: 無 | L5: 5 | M5: 無 | O5: 0 | P5: 0 | Q5: 無 | U5: 範例
A6: sanmeendo | B6: 5 | C6: 反門回刃 | D6: 20 | E6: 6 | F6: 6 | G6: 1 | H6: 0 | I6: =IF(A6="","",IFERROR(INDEX(武功總表!$E$2:$E$201,MATCH(A6,武功總表!$A$2:$A$201,0)),0)+N(H6)) | J6: 割傷 | K6: 無 | L6: 5 | M6: 無 | O6: 0 | P6: 0 | Q6: 無 | U6: 範例
I7: =IF(A7="","",IFERROR(INDEX(武功總表!$E$2:$E$201,MATCH(A7,武功總表!$A$2:$A$201,0)),0)+N(H7))
I8: =IF(A8="","",IFERROR(INDEX(武功總表!$E$2:$E$201,MATCH(A8,武功總表!$A$2:$A$201,0)),0)+N(H8))
I9: =IF(A9="","",IFERROR(INDEX(武功總表!$E$2:$E$201,MATCH(A9,武功總表!$A$2:$A$201,0)),0)+N(H9))
I10: =IF(A10="","",IFERROR(INDEX(武功總表!$E$2:$E$201,MATCH(A10,武功總表!$A$2:$A$201,0)),0)+N(H10))
I11: =IF(A11="","",IFERROR(INDEX(武功總表!$E$2:$E$201,MATCH(A11,武功總表!$A$2:$A$201,0)),0)+N(H11))
I12: =IF(A12="","",IFERROR(INDEX(武功總表!$E$2:$E$201,MATCH(A12,武功總表!$A$2:$A$201,0)),0)+N(H12))
I13: =IF(A13="","",IFERROR(INDEX(武功總表!$E$2:$E$201,MATCH(A13,武功總表!$A$2:$A$201,0)),0)+N(H13))
I14: =IF(A14="","",IFERROR(INDEX(武功總表!$E$2:$E$201,MATCH(A14,武功總表!$A$2:$A$201,0)),0)+N(H14))
I15: =IF(A15="","",IFERROR(INDEX(武功總表!$E$2:$E$201,MATCH(A15,武功總表!$A$2:$A$201,0)),0)+N(H15))
I16: =IF(A16="","",IFERROR(INDEX(武功總表!$E$2:$E$201,MATCH(A16,武功總表!$A$2:$A$201,0)),0)+N(H16))
I17: =IF(A17="","",IFERROR(INDEX(武功總表!$E$2:$E$201,MATCH(A17,武功總表!$A$2:$A$201,0)),0)+N(H17))
I18: =IF(A18="","",IFERROR(INDEX(武功總表!$E$2:$E$201,MATCH(A18,武功總表!$A$2:$A$201,0)),0)+N(H18))
... I201: =IF(A201="","",IFERROR(INDEX(武功總表!$E$2:$E$201,MATCH(A201,武功總表!$A$2:$A$201,0)),0)+N(H201))

Sheet 欄位說明
A1: 欄位 | B1: 意思 | C1: 可填範圍 | D1: 留白時的預設 | E1: 目前遊戲 已有？
A2: 【武功總表】
A3: 武功代號 | B3: 程式用的英文名，全小寫，可用 - 連接，例如 sanmeendo、tiger-blade。不能和別的武功重複。 | C3: 英文 | D3: （必填）
A4: 武功名稱 | B4: 遊戲裡顯示的中文名。 | C4: 中文 | D4: （必填） | E4: 有
A5: enable 在 | B5: 這套武功掛在哪個基本技能上（玩家 enable 時用）。 | C5: 下拉選單 | D5: （必填） | E5: 有
A6: 門派 | B6: 哪個門派的武功，方便分類，不影響數值。 | C6: 文字 | D6: 無
A7: 整套傷害加成 | B7: 整套武功共同的傷害加成。每一招都會加上這個數字。 | C7: 0～100 | D7: 0 | E7: NEW
A8: 加成方式 | B8: 「固定」：一學會就拿到全部加成。 「隨等級成長」：等級越高拿越多，200 級拿滿（例如 100 級拿一半）。 | C8: 下拉選單 | D8: 固定 | E8: NEW
A9: 武術造詣係數 | B9: 武功每升一級，給「武術造詣」= 新等級 × 係數。（龍圖心經用的是 10） | C9: 0～100 | D9: 0（不給） | E9: 有（龍圖心經）
A10: 武學之道起始等級 | B10: 武功練到這個等級後，每升一級開始給「武學之道」。 | C10: 0～200 | D10: 不給 | E10: 有（龍圖心經 50 級）
A11: 武學之道係數 | B11: 給「武學之道」=（新等級 − 起始等級 + 1）× 係數。 | C11: 0～100 | D11: 0 | E11: 有（龍圖心經）
A12: 整套特效 | B12: 整套武功共有的特殊效果。 「三招重演」（三門刀法）：最近三招都命中時，有機會立即把這三招再使一次；重演必中（不會被閃開或格開，防具照樣減傷），重演的招不算連中，發動後連中紀錄歸零。 | C12: 下拉選單 | D12: 無 | E12: NEW
A13: 整套特效機率 | B13: 條件達成時發動的基本機率。三招重演另加「天生膽識÷4」（小數捨去，不含裝備），寫在備註。 | C13: 0～100 | D13: 0 | E13: NEW
A14: 整套特效強度 | B14: 三招重演：重演那三招的傷害 %，以那招平常的傷害（含各種加成）為準，100 = 和平常一樣。 | C14: 0～300 | D14: 100 | E14: NEW
A15: 【招式表】
A16: 武功代號 | B16: 這一招屬於哪套武功，從「武功總表」已建立的代號中選。 | C16: 下拉選單 | D16: （必填）
A17: 順序 | B17: 招式的編號，用來對應第一部分寫的招式敘述。 | C17: 1～30 | D17: （必填）
A18: 招式名 | B18: 例如「三門齊開」。不用加「」。 | C18: 中文 | D18: （必填） | E18: 有
A19: 解鎖等級 | B19: 武功練到幾級才會使出這一招。 | C19: 0～200 | D19: 0（一開始就會） | E19: NEW
A20: 命中加成 | B20: 加在命中判定上。越高越容易打中。程式欄位 attack。 | C20: -30～30 | D20: 0 | E20: 有
A21: 防守加成 | B21: 出這招後，對手下一招比較難打中你。程式欄位 defense。 | C21: -30～30 | D21: 0 | E21: 有
A22: 內力加成 | B22: 有運內功時，額外增加的內力力道。程式欄位 force。 | C22: -30～30 | D22: 0 | E22: 有
A23: 招式傷害加成 | B23: 這一招自己的傷害加成，會和整套加成相加。可以填負數，代表這招傷害比較低（例如防守招）。 | C23: -50～100 | D23: 0 | E23: NEW
A24: 總傷害加成 | B24: 自動計算 = 整套加成 + 招式加成。 | C24: （自動）
A25: 傷害類型 | B25: 影響戰鬥訊息的用字，例如「割傷」會顯示「造成一道輕微的傷口」之類。 | C25: 下拉選單 | D25: 割傷（刀） | E25: 有
A26: 元素 | B26: 招式帶火、冰、雷、風屬性時，打中後會再加上裝備的同元素傷害。 | C26: 下拉選單 | D26: 無 | E26: 有
A27: 出招權重 | B27: 這招被選中的機率。5 是普通，10 是很常出，1 是很少出。 | C27: 1～10 | D27: 5 | E27: NEW
A28: 出招條件 | B28: 只在特定情況才會出的招，例如對手重傷時的殺招、格擋成功後的反擊。 | C28: 下拉選單 | D28: 無（隨時都可能出） | E28: NEW
A29: 連招前置 | B29: 出招條件選「連招」時才需要填：最近幾回合內要先用過哪些招，用逗號分隔。 | C29: 招式名
A30: 內力消耗 | B30: 使出這招要扣多少內力。內力不夠就不會出這招。 | C30: 0～500 | D30: 0 | E30: NEW
A31: 冷卻 | B31: 使出後要隔幾回合才能再出。 | C31: 0～20 | D31: 0（沒有冷卻） | E31: NEW
A32: 特效 | B32: 打中後的附加效果，見下方特效說明。 | C32: 下拉選單 | D32: 無 | E32: NEW
A33: 特效機率 | B33: 打中時發動特效的機率。 | C33: 0～100 | D33: 100 | E33: NEW
A34: 特效持續 | B34: 特效持續幾回合（追擊、震退這類一次性的不用填）。 | C34: 0～20 | D34: 1 | E34: NEW
A35: 特效強度 | B35: 依特效不同意思不同，見下方。 | C35: 0～100 | D35: 依特效 | E35: NEW
A36: 備註 | B36: 任何想說明的事。 | C36: 文字
A37: 【特效說明】
A38: 流血 | B38: 每回合扣血。強度 = 每回合扣多少點。
A39: 破防 | B39: 對手防具效果降低。強度 = 降低幾 %。
A40: 暈眩 | B40: 對手停手不能出招。強度不用填。
...

Sheet 建議範圍
A1: 項目 | B1: 入門武功 | C1: 中階武功 | D1: 高階 / 門派絕學 | E1: 說明
A2: 整套傷害加成 (%) | B2: 5～10 | C2: 10～20 | D2: 20～30 | E2: 高階武功建議搭配較低的防守加成或消耗，不要樣樣都強。
A3: 單招傷害加成 (%) | B3: -10～10 | C3: -10～20 | D3: -10～30 | E3: 同一套裡有強有弱：攻擊招高、防守招低甚至負數。
A4: 命中加成 | B4: 3～8 | C4: 5～10 | D4: 8～15 | E4: 目前三門刀法是 5～10、瘋虎刀法是 6～11。
A5: 防守加成 | B5: 2～8 | C5: -3～8 | D5: -8～10 | E5: 猛攻型武功防守可以是負的（瘋虎刀法是 -7～1）。
A6: 內力加成 | B6: 0～3 | C6: 0～8 | D6: 5～12 | E6: 瘋虎刀法 7～12 屬於重內力型。
A7: 招式數 | B7: 4～6 | C7: 6～8 | D7: 8～12
A8: 最高解鎖等級 | B8: 60 | C8: 120 | D8: 180
A9: 大招內力消耗 | B9: 10～30 | C9: 20～60 | D9: 50～150 | E9: 搭配冷卻 2～5 回合。
A10: 特效機率 (%) | B10: 10～20 | C10: 15～30 | D10: 20～40
A12: 以上皆為建議起點，實際數字等平衡模擬器做好後再調整。

Sheet 選單
A1: blade | B1: 割傷 | C1: 無 | D1: 無 | E1: 無 | F1: 固定 | G1: 無
A2: twohanded blade | B2: 刺傷 | C2: fire（火） | D2: 對手重傷時 | E2: 流血 | F2: 隨等級成長 | G2: 三招重演
A3: secondhand blade | B3: 瘀傷 | C3: ice（冰） | D3: 格擋成功後 | E3: 破防
A4: sword | B4: 斲傷 | C4: lightning（雷） | D4: 閃躲成功後 | E4: 暈眩
A5: twohanded sword | B5: 抓傷 | C5: wind（風） | D5: 連招 | E5: 緩速
A6: secondhand sword | B6: 咬傷 | E6: 吸血
A7: axe | E7: 追擊
A8: twohanded axe | E8: 震退
A9: secondhand axe
A10: pike
A11: twohanded pike
A12: secondhand pike
A13: staff
A14: twohanded staff
A15: secondhand staff
A16: blunt
A17: twohanded blunt
A18: secondhand blunt
A19: dagger
A20: secondhand dagger
... A24: unarmed
